<?xml version="1.0"?>

<robot xmlns:xacro="http://www.ros.org/wiki/xacro" >

    <!-- Specify some standard inertial calculations https://en.wikipedia.org/wiki/List_of_moments_of_inertia -->
    <!-- These make use of xacro's mathematical functionality -->
 
    <xacro:macro name="inertial_sphere" params="mass radius *origin">
        <inertial>
            <xacro:insert_block name="origin"/>
            <mass value="${mass}" />
            <inertia ixx="${(2/5) * mass * (radius*radius)}" ixy="0.0" ixz="0.0"
                    iyy="${(2/5) * mass * (radius*radius)}" iyz="0.0"
                    izz="${(2/5) * mass * (radius*radius)}" />
        </inertial>
    </xacro:macro>  
 
 
    <xacro:macro name="inertial_box" params="mass x y z *origin">
        <inertial>
            <xacro:insert_block name="origin"/>
            <mass value="${mass}" />
            <inertia ixx="${(1/12) * mass * (y*y+z*z)}" ixy="0.0" ixz="0.0"
                    iyy="${(1/12) * mass * (x*x+z*z)}" iyz="0.0"
                    izz="${(1/12) * mass * (x*x+y*y)}" />
        </inertial>
    </xacro:macro>
 
 
    <xacro:macro name="inertial_cylinder" params="mass length radius *origin">
        <inertial>
            <xacro:insert_block name="origin"/>
            <mass value="${mass}" />
            <inertia ixx="${(1/12) * mass * (3*radius*radius + length*length)}" ixy="0.0" ixz="0.0"
                    iyy="${(1/12) * mass * (3*radius*radius + length*length)}" iyz="0.0"
                    izz="${(1/2) * mass * (radius*radius)}" />
        </inertial>
    </xacro:macro>


    <xacro:macro name="wheel_joint" params="name parent child xyz side damping friction max_effort max_velocity">
      <joint name="${name}" type="continuous">
        <parent link="${parent}" />
        <child link="${child}" />

        <xacro:if value="${side == 'left'}">
            <origin xyz="${xyz}" rpy="-${pi/2} 0 0"/>
            <axis xyz="0 0 -1"/>
        </xacro:if>
        <xacro:if value="${side == 'right'}">
            <origin xyz="${xyz}" rpy="${pi/2} 0 0"/>
            <axis xyz="0 0 1"/>
        </xacro:if>
        <dynamics damping="${damping}" friction="${friction}"/>     
        <limit effort="${max_effort}" velocity="${max_velocity}"/>
      </joint>
    </xacro:macro>
    <!--<joint_properties damping="1.0" friction="1.0"/> -->


    <xacro:macro name="wheel_link" params="name in_radius in_length in_mass">
        <link name="${name}">
            <visual>
                <geometry> <!-- the weheels are 60mm diameter, 25mm thick. -->
                    <cylinder radius="${in_radius}" length="${in_length}"/>
                </geometry>
                <material name="black"/>
            </visual>

            <collision>
                <origin xyz="0 0 0" rpy="0 0 0"/>
                <geometry>
                    <cylinder length="${in_length}" radius="${in_radius}" />
                </geometry>
            </collision>
            <xacro:inertial_cylinder mass="${in_mass}" length="${in_length}" radius="${in_radius}">
                <!-- I think the origin is the centre of mass - middle of the cylinder -->
                <origin xyz="0 0 0" rpy="0 0 0"/>
            </xacro:inertial_cylinder>
        </link>
    </xacro:macro>


    <xacro:macro name="ros2control_wheel" params="joint_name cmd_min cmd_max">
        <joint name="${joint_name}">
            <command_interface name="velocity">
                <param name="min">${cmd_min}</param>
                <param name="max">${cmd_max}</param>
            </command_interface>
            <state_interface name="velocity"/>
            <state_interface name="position"/>
        </joint>
    </xacro:macro>



    <!-- materials -->

    <material name="white">
        <color rgba="1 1 1 1" />
    </material>

    <material name="orange">
        <color rgba="1 0.3 0.1 1" />
    </material>

    <material name="blue">
        <color rgba="0.2 0.2 1 1" />
    </material>

    <material name="black">
        <color rgba="0 0 0 1" />
    </material>
</robot>